test("Test should pass if resolved", async () => {
  try {
    const result = await new Promise((resolve, reject) => {
      resolve(true);
    });
    expect(result).toBe(true);
  } catch (error) {
    // Handle any unexpected errors here
    throw error;
  }
});
